file:/home/ningkw/Agentable/Experment_Agent/Agent/Group_1_python/llm_agents/llm_agents/agent.py, class:Agent. 
Exist LOPE Defects in method decide_next_action. Detail: In the function 'decide_next_action', the input is a single parameter 'prompt', which is passed directly to the 'generate' method of 'self.llm' without any validation or error handling. This means that if 'prompt' is None, an empty string, or otherwise invalid, it could lead to errors when 'generate' is called. Additionally, the output of the 'generate' method is also not subjected to any fault tolerance checks. The generated output is directly parsed by the '_parse' method without verifying if 'generated' is in the expected format or if it contains any errors. Therefore, both the input and output lack proper fault tolerance mechanisms, which could result in uncaught exceptions during execution.

file:/home/ningkw/Agentable/Experment_Agent/Agent/Group_1_python/openagi/src/openagi/agent.py, class:Admin. 
Exist LOPE Defects in method worker_task_execution. Detail: The method 'worker_task_execution' calls 'execute_task' without any checks or validations on the inputs (specifically 'cur_task' and 'context') before the call. If 'cur_task' is invalid or if the context derived from 'get_previous_task_contexts' is not appropriate, this could lead to errors during the execution of 'execute_task'. Furthermore, there is no error handling or fault tolerance mechanism implemented after the call to 'execute_task' to manage potential exceptions or errors that could arise from its execution. Therefore, both the inputs and outputs lack any form of fault tolerance.

file:/home/ningkw/Agentable/Experment_Agent/Agent/Group_1_python/openagi/src/openagi/agent.py, class:Admin. 
Exist LOPE Defects in method single_agent_execution. Detail: In the 'single_agent_execution' method, the input to the 'self.llm.run(prompt)' function is constructed from various variables, including 'base_prompt' and 'all_thoughts_and_obs'. However, there are no checks or validations on these inputs before calling 'run', indicating a lack of fault tolerance for the inputs. The function does, however, implement some fault tolerance for outputs after calling 'run'. It checks the output using '_should_continue(observations)' and handles potential errors by logging warnings and attempting to recover from them. If the output does not meet expectations after the maximum iterations, it raises an exception. This indicates that while there are mechanisms to handle output errors, the inputs lack any form of validation or fault tolerance.

file:/home/ningkw/Agentable/Experment_Agent/Agent/Group_2_python/Trace/opto/optimizers/optimizer.py, class:Optimizer. 
Exist LOPE Defects in method propose. Detail: The 'propose' method directly calls the '_step' function with the arguments passed to it via *args and **kwargs. There are no checks or validations on the inputs before they are passed to '_step', which means if the inputs are invalid or cause an error, it could lead to exceptions being raised without any handling. Additionally, there is no error handling or fault tolerance mechanism implemented after the call to '_step' to manage its outputs. If '_step' raises an error or returns an unexpected output, the 'propose' method does not have any logic to handle such cases. Therefore, both the inputs and outputs lack fault tolerance.

file:/home/ningkw/Agentable/Experment_Agent/Agent/Group_2_python/Trace/examples/virtualhome.py, class:VirtualHomeEnv. 
Exist LOPE Defects in method env_step. Detail: The method 'env_step' calls the function 'step' from 'self.env' with 'dict_actions' as an input. However, there is no validation or fault tolerance implemented for 'dict_actions' before it is passed to 'self.env.step'. This means if 'dict_actions' is of an incorrect type, has missing required fields, or contains invalid values, it could lead to unexpected behavior or exceptions during execution.

file:/home/ningkw/Agentable/Experment_Agent/Agent/Group_2_python/Trace/opto/optimizers/optoprime.py, class:OptoPrime. 
Exist LOPE Defects in method _step. Detail: In the provided code, the method '_step' prepares inputs for the 'call_llm' function by constructing 'system_prompt' and 'user_prompt', but there are no checks or validations implemented to ensure that these inputs are valid or safe before they are passed to 'call_llm'. This lack of input validation means that if 'system_prompt' or 'user_prompt' contains unexpected values or formats, it could lead to errors when 'call_llm' executes. Additionally, there is no error handling surrounding the call to 'call_llm', which means that if an error occurs during the execution of 'call_llm', it will not be caught, and the program may crash or behave unexpectedly. After calling 'call_llm', the response is checked for the presence of 'TERMINATE', but there is no comprehensive error handling for other potential issues that could arise from 'call_llm'. The subsequent operations (like extracting suggestions and constructing an update dictionary) assume that 'response' is valid, which may not always be the case. Thus, both the input preparation and the output handling lack fault tolerance mechanisms.

file:/home/ningkw/Agentable/Experment_Agent/Agent/Group_2_python/Trace/opto/optimizers/optoprime.py, class:OptoPrime. 
Exist LOPE Defects in method _step. Detail: In the provided code, the function '_step' calls 'call_llm' with 'system_prompt' and 'user_prompt' as inputs. However, there is no validation or error handling for these inputs before they are passed to 'call_llm', which could lead to potential errors if the prompts are malformed or contain unexpected data. Additionally, the output of 'call_llm' is directly used in subsequent operations without checking for the presence of errors or validating its structure. While there is a check for the keyword 'TERMINATE' in the response, this is not a comprehensive fault tolerance mechanism. The absence of checks for other potential issues (e.g., malformed responses, exceptions raised by 'call_llm') indicates a lack of fault tolerance for both inputs and outputs.

file:/home/ningkw/Agentable/Experment_Agent/Agent/Group_2_python/Trace/opto/optimizers/optoprime.py, class:OptoPrime. 
Exist LOPE Defects in method _step. Detail: The function '_step' calls 'construct_prompt' with the inputs 'summary' and 'mask'. However, there is no validation or error handling around these inputs before they are passed to 'construct_prompt', which could lead to potential issues if 'summary' or 'mask' are invalid or None. Additionally, the outputs 'system_prompt' and 'user_prompt' from 'construct_prompt' are used directly in subsequent function calls without any checks for their validity or error handling. If 'construct_prompt' raises an exception or returns unexpected values, the function '_step' would not handle these scenarios, leading to a lack of fault tolerance.

file:/home/ningkw/Agentable/Experment_Agent/Agent/Group_2_python/NanoLLM/nano_llm/agents/chat.py, class:ChatAgent. 
Exist LOPE Defects in method __init__. Detail: In the __init__ method, the print_input_prompt function is called without any prior checks or validations on the inputs or the state of the system. The inputs to the function are derived from the class attributes set during initialization, but there is no explicit error handling to ensure that these inputs are valid or safe to use. Additionally, after the call to print_input_prompt, there is no handling of potential exceptions or errors that may arise from its execution. This indicates a lack of fault tolerance for both the input into print_input_prompt and the output from it.

file:/home/ningkw/Agentable/Experment_Agent/Agent/Group_2_python/NanoLLM/nano_llm/agents/dynamic_agent.py, class:DynamicAgent. 
Exist LOPE Defects in method add_plugin. Detail: In the 'add_plugin' method, the input parameters such as 'type', 'wait', 'start', 'state_dict', and 'layout_node' are directly used without any validation or fault tolerance checks before calling the 'run' method. This means that if any of these inputs are invalid or lead to exceptions, the method may fail without any handling. However, after the call to 'run', there is some fault tolerance present in terms of output because the method logs messages regarding the loading of the plugin and sends alerts based on the load time. Additionally, if an exception occurs while adding a plugin, it is caught and logged, which provides some level of fault tolerance for the output process.

file:/home/ningkw/Agentable/Experment_Agent/Agent/Group_2_python/NanoLLM/nano_llm/agent.py, class:Agent. 
Exist LOPE Defects in method __call__. Detail: The method '__call__' in the provided code directly calls the 'process' function with the inputs 'input', 'channel', and '**kwargs'. However, there is no indication of any validation or error handling mechanisms for the 'input' parameter before it is passed to 'process'. Similarly, there is no error handling or fault tolerance implemented for the output returned by 'process'. This means that if 'process' raises an error due to invalid inputs or if it returns an unexpected output, it will not be handled, leading to potential crashes or unhandled exceptions.

file:/home/ningkw/Agentable/Experment_Agent/Agent/Group_2_python/NanoLLM/nano_llm/agents/video_query.py, class:VideoQuery. 
Exist LOPE Defects in method start. Detail: The 'start' method is called without any explicit error handling or validation for its inputs. The inputs to 'start' are primarily derived from the initialization of the class, and while certain parameters are set with defaults (like 'model' and 'vision_scaling'), there is no validation or fault tolerance mechanism that checks the integrity or validity of these parameters before calling 'self.server.start()'. Additionally, after calling 'start', there is no handling of potential exceptions that could arise, such as failure to start the server or websocket connection issues. This lack of error handling could lead to unhandled exceptions if the server fails to start, resulting in a crash or undefined behavior.

file:/home/ningkw/Agentable/Experment_Agent/Agent/Group_2_python/NanoLLM/nano_llm/agents/web_chat.py, class:WebChat. 
Exist LOPE Defects in method start. Detail: The 'start' method does not perform any checks or validations on the inputs it receives (in this case, it does not take any parameters). As such, there is no fault tolerance for inputs before calling 'start'. Additionally, the method calls 'super().start()' and 'self.server.start()', but there is no error handling or logging implemented to manage potential exceptions that may arise from these calls. Therefore, there is also no fault tolerance for outputs after calling 'start'.

file:/home/ningkw/Agentable/Experment_Agent/Agent/Group_2_python/AutoWebGLM/webarena/agent/agent.py, class:PromptAgent. 
Exist LOPE Defects in method next_action. Detail: In the 'next_action' method, the function 'construct' is called with inputs 'trajectory', 'intent', and 'meta_data'. There is no explicit fault tolerance mechanism implemented for these inputs before calling 'construct', meaning any invalid or unexpected values could lead to an error in the function. After calling 'construct', the output 'prompt' is used to call another function 'call_llm', and the response from this function is parsed. If an error occurs during parsing, a retry mechanism is implemented, which provides some fault tolerance. If the maximum number of retries is exceeded, a default action created by 'create_none_action()' is returned, indicating a form of fault tolerance for the output. Overall, while the output handling has fault tolerance, the input handling does not.

file:/home/ningkw/Agentable/Experment_Agent/Agent/Group_2_python/AutoWebGLM/webarena/agent/prompts/prompt_constructor.py, class:DirectPromptConstructor. 
Exist LOPE Defects in method construct. Detail: In the provided code, the function 'construct' calls 'get_lm_api_input' with three parameters: 'intro', 'examples', and 'current'. There are no checks or validations performed on these inputs before the function call, meaning if any of these inputs are invalid or None, it could lead to runtime errors in 'get_lm_api_input'. Additionally, there are no try-except blocks or any other mechanisms to handle potential errors that could arise during the execution of 'get_lm_api_input'. Consequently, the outputs from 'get_lm_api_input' are not validated or handled either, which means if an error occurs during its execution, it could propagate back to the 'construct' function without any fault tolerance mechanisms in place. Overall, both input and output lack fault tolerance.

file:/home/ningkw/Agentable/Experment_Agent/Agent/Group_2_python/CrewAI-Studio/app/my_agent.py, class:MyAgent. 
Exist LOPE Defects in method get_crewai_agent. Detail: The function 'get_crewai_agent' calls 'create_tool' within a list comprehension as part of building the 'tools' list. There is no explicit validation or error handling for the inputs to 'create_tool' prior to its invocation. If any of the 'tool' objects in 'self.tools' are invalid or if 'create_tool' itself raises an exception, this will lead to a failure without any fault tolerance mechanism in place. Furthermore, there is no error handling after calling 'create_tool', meaning that if an error occurs during this call, it will propagate without any catch or recovery, which can lead to unhandled exceptions. Therefore, both input and output lack fault tolerance.

file:/home/ningkw/Agentable/Experment_Agent/Agent/Group_2_python/CrewAI-Studio/app/my_crew.py, class:MyCrew. 
Exist LOPE Defects in method get_crewai_crew. Detail: The function get_crewai_crew retrieves crewai_agents by calling get_crewai_agent on each agent in self.agents. There is no explicit error handling or validation of the inputs (self.agents, tasks, etc.) before calling get_crewai_agent, which could lead to exceptions if any agent fails to provide a valid response. Additionally, the output from get_crewai_agent is not checked for validity or errors after the call, meaning if any agent encounters an error, it could propagate through the system without any fault tolerance mechanisms in place.

file:/home/ningkw/Agentable/Experment_Agent/Agent/Group_2_python/ControlFlow/src/controlflow/agents/agent.py, class:Agent. 
Exist LOPE Defects in method run. Detail: The 'run' function accepts several parameters: 'objective', 'turn_strategy', 'handlers', 'stream', and '**task_kwargs'. However, the code does not demonstrate any validation or error handling for these inputs before calling the 'controlflow.run' method. For example, there is no type checking or default value handling for 'objective' or other optional parameters. This lack of validation means that if an invalid input is provided, it could lead to an exception or unexpected behavior. Similarly, the output of the 'run' function is returned directly from 'controlflow.run', without any error handling or checks on the returned value. If 'controlflow.run' encounters an error, the 'run' function would propagate that error without any fault tolerance mechanisms in place. Thus, both input and output lack fault tolerance.

file:/home/ningkw/Agentable/Experment_Agent/Agent/Group_2_python/ControlFlow/src/controlflow/agents/agent.py, class:Agent. 
Exist LOPE Defects in method get_prompt. Detail: In the provided code, the target function 'render' is called within the 'get_prompt' method. The input to the 'render' function is the 'template' object, which is created using 'prompt_templates.AgentTemplate(template=self.prompt, agent=self)'. There is no validation or error handling for 'self.prompt' or 'self' before this call, meaning if either of these inputs is invalid (e.g., 'self.prompt' is None or not a valid template), it could lead to an error when 'render' is executed. Additionally, there is no fault tolerance mechanism after the 'render' call to handle potential exceptions that could arise from rendering the template, such as issues with the template syntax or other runtime errors. Therefore, the method lacks fault tolerance for both the input to 'render' and the output from 'render'.

Exist LOPE Defects in method test_agent_run_with_handlers. Detail: In the provided function, the input to the 'run' method is a string 'Calculate 2 + 2', along with other parameters such as 'result_type', 'handlers', and 'max_llm_calls'. There is no validation or error handling for this input before calling 'run', meaning that if the input were invalid (for example, if it were None or an unexpected type), it could lead to errors during execution. Similarly, after the 'run' method is called, the output is not explicitly validated for errors or exceptions. The assertions that check the length of 'handler.events' and 'handler.agent_messages' do not account for potential failures or issues that could arise from the 'run' method itself. Therefore, there is a lack of fault tolerance both for the inputs before the call to 'run' and for the outputs after the call.

file:/home/ningkw/Agentable/Experment_Agent/Agent/Group_2_python/ControlFlow/tests/agents/test_agents.py, class:TestHandlers. 
Exist LOPE Defects in method test_agent_run_with_handlers. Detail: In the provided code, the method 'test_agent_run_with_handlers' calls the 'run' method of the 'Agent' class with specific inputs: a string 'Calculate 2 + 2', a result type of int, a list of handlers, and a maximum number of LLM calls. The code does not include any checks or validations for the input parameters before calling 'run'. This lack of input validation indicates a lack of fault tolerance for the input. 

file:/home/ningkw/Agentable/Experment_Agent/Agent/Group_2_python/ControlFlow/src/controlflow/orchestration/orchestrator.py, class:Orchestrator. 
Exist LOPE Defects in method compile_prompt. Detail: In the provided code, the function 'compile_prompt' does not implement any fault tolerance mechanisms for the inputs before calling 'model_instructions'. Specifically, it directly calls 'llm_rules.model_instructions()' without checking if 'llm_rules' is valid or if 'model_instructions()' might raise an exception due to any underlying issues (e.g., missing data, invalid state). Similarly, there is no fault tolerance for the output after calling 'model_instructions', as the result is directly used in the creation of the list 'prompts' without any error handling or validation. If 'model_instructions()' raises an exception, it would propagate up and lead to a failure of the 'compile_prompt' method without any recovery mechanisms in place.

file:/home/ningkw/Agentable/Experment_Agent/Agent/Group_2_python/ControlFlow/src/controlflow/orchestration/orchestrator.py, class:Orchestrator. 
Exist LOPE Defects in method compile_messages. Detail: The function 'compile_messages' calls 'compile_to_messages' without any explicit error handling or validation of the inputs. The input to 'compile_to_messages' is derived from the 'MessageCompiler' instance, which is created using 'events' obtained from 'self.flow.get_events()' and other parameters. If 'self.flow.get_events()' fails or returns an unexpected result, there is no fault tolerance implemented to handle such cases. Similarly, after calling 'compile_to_messages', the output is directly returned without any checks to ensure that the output is valid or as expected. In the absence of try-except blocks or validation checks for both inputs and outputs, there is a lack of fault tolerance in the 'compile_messages' method.

file:/home/ningkw/Agentable/Experment_Agent/Agent/Group_2_python/ControlFlow/src/controlflow/tasks/task.py, class:Task. 
Exist LOPE Defects in method get_prompt. Detail: The function `get_prompt` is responsible for generating a prompt by utilizing a template from `prompt_templates`. The `render` method is called on the `template` object, which is an instance of `TaskTemplate`. There is no validation or fault tolerance mechanism in place for the inputs to the `render` method, which means if the template or any of its parameters are invalid or lead to an error, it would result in an unhandled exception. Similarly, the output of the `render` method is returned directly without any error handling or validation. If the `render` method fails, the function will not return a valid string, leading to potential issues in the calling context. Therefore, both the input to `render` and the output from it lack fault tolerance.

file:/home/ningkw/Agentable/Experment_Agent/Agent/Group_2_python/ControlFlow/src/controlflow/flows/flow.py, class:Flow. 
Exist LOPE Defects in method get_prompt. Detail: In the provided code, the 'get_prompt' function constructs a prompt by initializing a 'FlowTemplate' object with 'self.prompt' and 'self'. The 'render' method is then called on this template object. However, there are no mechanisms in place to validate the inputs (i.e., 'self.prompt' and 'self') before calling 'render'. If either of these inputs is invalid (e.g., if 'self.prompt' is None or not a string), it could lead to an error during the execution of 'render'. Similarly, there is no error handling implemented after the call to 'render' to manage any exceptions that may arise from rendering the template. Therefore, both the input to 'render' and the output from it lack fault tolerance.

file:/home/ningkw/Agentable/Experment_Agent/Agent/Group_2_python/SaltAI_Language_Toolkit/nodes/readers.py, class:LLMSaltWebCrawler. 
Exist LOPE Defects in method crawl. Detail: The method 'crawl' performs several checks on its inputs before proceeding to call the 'to_documents' method. Specifically, it checks if the input URL is not empty and validates it using the 'valid_url' function. If both the URL and the list of URLs are empty, it raises an exception, ensuring that the function does not proceed with invalid input. Additionally, it logs the valid URLs, which provides some level of oversight on the input being processed. However, there is no fault tolerance mechanism for the output of the 'to_documents' method. If 'to_documents' raises an exception or returns an unexpected result, it is not handled, which could lead to unhandled errors in the calling code.

file:/home/ningkw/Agentable/Experment_Agent/Agent/Group_2_python/SaltAI_Language_Toolkit/nodes/query.py, class:LLMChatEngine. 
Exist LOPE Defects in method chat. Detail: The 'chat' function takes three parameters: 'llm_index', 'query', and 'reset_engine'. However, there is no validation or error handling for the 'query' input before it is passed to 'self.chat_engine.chat(query)'. If 'query' is None or not a string, it may lead to runtime errors without any fault tolerance mechanisms in place. Additionally, there is no error handling for the output of 'self.chat_engine.chat(query)'. If the 'chat' method on 'self.chat_engine' fails or returns an unexpected value, the function does not account for those scenarios. Therefore, both the inputs and outputs lack fault tolerance.

file:/home/ningkw/Agentable/Experment_Agent/Agent/Group_2_python/agentcloud/agent-backend/src/chat/chat_assistant.py, class:ChatAssistant. 
Exist LOPE Defects in method run. Detail: The function 'run' does not implement any fault tolerance mechanisms for its input or output. It directly calls 'asyncio.run(self.chat_agent.stream_execute())', which means it relies on 'self.chat_agent' and its method 'stream_execute()' to handle any exceptions that may occur during execution. There are no try-except blocks or input validations present in the 'run' function or before it is called, meaning that if 'self.chat_agent' is not properly initialized or if 'stream_execute()' raises an exception, it will not be handled gracefully. Additionally, the output of 'stream_execute()' is not captured or validated, indicating a lack of fault tolerance for outputs as well.

file:/home/ningkw/Agentable/Experment_Agent/Agent/Group_2_python/AIlice/ailice/core/AProcessor.py, class:AProcessor. 
Exist LOPE Defects in method __init__. Detail: In the provided code, the function GetModel is called directly with inputs modelID and promptName without any validation or error handling mechanisms to ensure that these inputs are valid. If either of these inputs is invalid (e.g., modelID does not exist or promptName is incorrect), it could lead to runtime errors. Additionally, there is no fault tolerance implemented after the call to GetModel to handle potential exceptions or errors it may throw, which could propagate and affect the stability of the __init__ method. Therefore, both input and output lack fault tolerance mechanisms.

file:/home/ningkw/Agentable/Experment_Agent/Agent/Group_2_python/AIlice/ailice/core/AProcessor.py, class:AProcessor. 
Exist LOPE Defects in method __call__. Detail: In the provided code, the method '__call__' is responsible for invoking the Generate function from the 'llm' object. Before calling Generate, the input is prepared using a prompt built by the 'BuildPrompt' method. However, there is no explicit check or validation of the 'prompt' variable to ensure it is in a valid state before being passed to Generate. This lack of input validation could lead to issues if the prompt is malformed or empty.

file:/home/ningkw/Agentable/Experment_Agent/Agent/Group_2_python/AIlice/ailice/core/AProcessor.py, class:AProcessor. 
Exist LOPE Defects in method __call__. Detail: In the provided code, the target function 'Generate' is called within a loop that doesn't explicitly check for the validity of the input 'prompt' before passing it to 'Generate'. While 'txt' is passed to 'self.conversation.Add' and 'self.EvalStore' before the call, there is no validation or error handling for 'txt' itself. If 'txt' is invalid or malformed, it could lead to issues when 'Generate' is called. However, after 'Generate' is called, there is a mechanism in place to handle the output by checking if the returned value 'ret' is empty. If it is, a default error message is assigned to 'ret'. This indicates that there is a form of fault tolerance after the function call, but not before. Thus, the overall assessment shows a lack of fault tolerance for the input before calling 'Generate'.

file:/home/ningkw/Agentable/Experment_Agent/Agent/Group_2_python/rosa/src/turtle_agent/scripts/turtle_agent.py, class:TurtleAgent. 
Exist LOPE Defects in method __init__. Detail: The method '__init__' contains lambda functions in the 'command_handler' dictionary that call the 'submit' function with inputs from 'get_help(self.examples)' and 'self.choose_example()'. However, there are no checks or validations on the inputs being passed to 'submit'. For instance, 'get_help(self.examples)' and 'self.choose_example()' could return values that are invalid or lead to exceptions when processed by 'submit'. Therefore, there is no fault tolerance implemented prior to the call to 'submit'. Similarly, since the return values of 'submit' are not handled or validated after the call, there is no fault tolerance for the outputs either. In summary, both inputs and outputs lack any form of error handling or validation, making the implementation prone to faults.

file:/home/ningkw/Agentable/Experment_Agent/Agent/Group_2_python/SWE-agent/sweagent/agent/agents.py, class:Agent. 
Exist LOPE Defects in method forward_model. Detail: The method 'forward_model' includes a fault tolerance mechanism for the input by using a try-except block to handle JSON decoding errors when parsing the 'state' input. If the 'state' input is not valid JSON, it raises a ValueError with a detailed message. However, there is no explicit fault tolerance implemented for the output after calling 'query'. The method does not check for the validity or format of the output returned from 'self.model.query', which could potentially lead to issues if the output is malformed or unexpected.

file:/home/ningkw/Agentable/Experment_Agent/Agent/Group_2_python/automata/automata/experimental/tools/builders/agentified_search_builder.py, class:AgentifiedSearchToolkitBuilder. 
Exist LOPE Defects in method _agent_selected_best_match. Detail: The method '_agent_selected_best_match' takes two parameters: 'query' (a string) and 'query_result' (an instance of SymbolSimilarityResult). Before the call to 'standalone_call', the input is formatted into 'formatted_input_prompt', but there are no checks to ensure that 'formatted_input_prompt' is valid, nor is there any validation of 'query' or 'query_result'. Therefore, if either of these inputs is invalid or malformed, it could lead to errors when calling 'standalone_call'. After calling 'standalone_call', the output is stripped of whitespace, but there is no error handling for cases where 'standalone_call' might fail (e.g., due to a network error, an API issue, or receiving unexpected output). Additionally, the code does not check if 'best_match_dotpath' is a valid value before proceeding to find the selected symbol, which can lead to potential failures if 'best_match_dotpath' is empty or malformed. Overall, there is no fault tolerance implemented before or after the call to 'standalone_call'.

file:/home/ningkw/Agentable/Experment_Agent/Agent/Group_2_python/automata/automata/agent/openai_agent.py, class:OpenAIAutomataAgent. 
Exist LOPE Defects in method __next__. Detail: In the provided code, the method '__next__' calls the function 'get_next_assistant_completion' without any explicit checks or fault tolerance mechanisms for the input parameters or the output. The only checks present are before the call to 'get_next_assistant_completion', which ensure that the task has not been completed and that the maximum iteration count has not been exceeded. However, there are no validations on the inputs to 'get_next_assistant_completion', such as ensuring that the chat provider is properly initialized or that any required state is valid. Additionally, the output from 'get_next_assistant_completion' is directly used without any error handling or verification, which means that if an error occurs during the function call (e.g., if it raises an exception), or if the output is in an unexpected format, the method could fail without any fault tolerance. Therefore, both input and output lack necessary fault tolerance mechanisms.

file:/home/ningkw/Agentable/Experment_Agent/Agent/Group_2_python/automata/automata/agent/openai_agent.py, class:OpenAIAutomataAgent. 
Exist LOPE Defects in method set_database_provider. Detail: In the function 'set_database_provider', there is a fault tolerance mechanism for the input 'provider' before calling 'save_message'. The code checks if 'provider' is an instance of 'LLMConversationDatabaseProvider' and raises an 'AgentDatabaseError' if it is not. Additionally, it checks if 'self.database_provider' is already set, raising another error if so. However, when calling 'save_message', there is no error handling implemented for the output. If 'save_message' fails (for instance, due to database issues), the code does not catch or handle any exceptions that may arise from that call, leading to a lack of fault tolerance for the output after calling 'save_message'.

file:/home/ningkw/Agentable/Experment_Agent/Agent/Group_2_python/automata/automata/agent/openai_agent.py, class:OpenAIAutomataAgent. 
Exist LOPE Defects in method _build_initial_messages. Detail: The function '_build_initial_messages' checks whether the 'instruction_formatter' dictionary contains the key 'user_input_instructions'. If this key is missing, it raises a KeyError, which provides fault tolerance for the input by ensuring that the function does not proceed with invalid data. However, there is no explicit fault tolerance mechanism implemented for the output after the 'get' method is called on the 'function_call' dictionary. If 'function_call' is not present, the code does handle that by setting 'function_call' to None, but once the 'OpenAIChatMessage' is created, there are no checks to ensure that the resulting 'input_messages' list is valid or that it contains messages in the expected format. Therefore, while there is some input fault tolerance, there is a lack of output fault tolerance.

file:/home/ningkw/Agentable/Experment_Agent/Agent/Group_2_python/automata/automata/eval/agent/agent_eval_database.py, class:AgentEvalResultDatabase. 
Exist LOPE Defects in method write_result. Detail: In the method 'write_result', there is a check for the 'session_id' of the 'eval_result' object before calling 'to_payload'. If 'session_id' is not set, a 'ValueError' is raised, providing fault tolerance for the input to 'to_payload'. However, after calling 'to_payload', the output is passed to 'create_payload' without any error handling. If 'to_payload' returns an unexpected result (like None or an invalid format), there is no mechanism in place to handle such errors. Therefore, while there is fault tolerance for the input, there is a lack of fault tolerance for the output.

file:/home/ningkw/Agentable/Experment_Agent/Agent/Group_2_python/automata/automata/tasks/task_base.py, class:Task. 
Exist LOPE Defects in method get. Detail: The provided code contains a class constructor (__init__) that initializes various attributes of a task object. The constructor checks for the presence of certain keyword arguments (kwargs) to set the session_id, priority, and max_retries. However, there is no explicit fault tolerance mechanism for validating the inputs before calling the 'get' method. For instance, it does not handle cases where invalid types or values are passed in kwargs (e.g., priority being a negative number). After the 'get' method is called, there is also no indication of fault tolerance for the output; it simply stores the result and error attributes without checking for validity or handling exceptions. Overall, while there are some checks for conflicting inputs (session_id and generate_deterministic_id), the overall fault tolerance for both inputs and outputs is lacking.

file:/home/ningkw/Agentable/Experment_Agent/Agent/Group_2_python/automata/research/study_agency/study_leetcode/leetcode_solutions_finder.py, class:LeetCodeSolutionsFinder. 
Exist LOPE Defects in method get_embedding. Detail: The method 'get_embedding' takes a single string input 'document' and calls the 'build_embedding_vector' function with it. There is no validation or error handling for the input 'document' before it is passed to 'build_embedding_vector'. If 'document' is None, an empty string, or an improperly formatted string, it could lead to errors in 'build_embedding_vector'. Additionally, there is no error handling for the output of 'build_embedding_vector'. If this function raises an exception or returns an unexpected result (e.g., a None or an invalid array), 'get_embedding' does not address this, which could lead to further issues downstream. Overall, both input and output lack fault tolerance mechanisms.

file:/home/ningkw/Agentable/Experment_Agent/Agent/Group_2_python/automata/automata/eval/agent/code_writing_eval.py, class:CodeWritingEval. 
Exist LOPE Defects in method extract_action. Detail: In the provided code, the method 'extract_action' does not have explicit fault tolerance mechanisms for the input before calling the 'get' method. The method checks if 'message' is an instance of 'OpenAIChatMessage' and if it has a valid 'function_call'. However, this does not cover all possible input scenarios (e.g., malformed messages or unexpected types). Additionally, there is no validation for the content of 'arguments' before accessing 'arguments['result']', which could lead to KeyErrors if 'result' is not present. 

file:/home/ningkw/Agentable/Experment_Agent/Agent/Group_2_python/automata/automata/experimental/tools/builders/symbol_search_builder.py, class:SymbolSearchToolkitBuilder. 
Exist LOPE Defects in method _symbol_agent_search_processor. Detail: In the provided code, the method '_symbol_agent_search_processor' calls 'standalone_call' with the variable 'formatted_input_prompt'. There is no validation or handling of the 'query' input before it is processed and passed to 'standalone_call'. If 'query' is None or an empty string, it may lead to unexpected behavior or errors. Additionally, there is no error handling for the output from 'standalone_call'. If the call fails or returns an unexpected result, this could lead to issues when the output is used in the subsequent logic. Specifically, the code assumes that 'result' will always be a valid string that can be checked against 'search_results'. Therefore, both the input and output lack fault tolerance mechanisms.

file:/home/ningkw/Agentable/Experment_Agent/Agent/Group_2_python/automata/research/study_agency/study_leetcode/leetcode_problem_solver.py, class:LeetCodeSolver. 
Exist LOPE Defects in method _get_agent_config. Detail: In the _get_agent_config method, the inputs are 'system_prompt' (a string) and 'solutions_finder' (an instance of LeetCodeSolutionsFinder). There is no validation or error handling implemented for these inputs before they are passed to the build_for_open_ai function. If either of these inputs is invalid (e.g., an empty string for system_prompt or None for solutions_finder), it could lead to runtime errors within build_for_open_ai. In the provided code, the method '_get_agent_config' calls 'build_for_open_ai' without any checks or validations on the input parameters 'system_prompt' and 'solutions_finder'. If either of these inputs is invalid (e.g., 'system_prompt' is None or not a string, or 'solutions_finder' is not a valid instance of 'LeetCodeSolutionsFinder'), it could lead to runtime exceptions when 'build_for_open_ai' is executed. Furthermore, there is no error handling to manage potential exceptions that may arise from calling 'build_for_open_ai', which could impact the stability of the application. The outputs from 'build_for_open_ai' are directly used to create an 'OpenAIAutomataAgentConfig' object without any validation or error handling, meaning that if 'build_for_open_ai' returns an unexpected value or raises an error, it could lead to further problems downstream.

file:/home/ningkw/Agentable/Experment_Agent/Agent/Group_2_python/automata/research/study_agency/study_leetcode/leetcode_problem_solver.py, class:LeetCodeSolver. 
Exist LOPE Defects in method add_best_related_leetcode_solution. Detail: The function add_best_related_leetcode_solution accepts three parameters: problem_header, agent, and solutions_finder. There is no validation or error handling for these inputs before they are used. For example, if problem_header is None or an empty string, it could lead to issues when constructing the initial_query or when calling solutions_finder.find_best_match_and_explanation. Similarly, if agent or solutions_finder are not properly instantiated, it could lead to attribute errors when calling their methods. After calling add_message, there is no error handling or fault tolerance for the output. If the solution variable is None or an invalid type, it could cause issues when creating the user_message or when calling agent.chat_provider.add_message. Therefore, both the inputs and outputs lack fault tolerance mechanisms.

file:/home/ningkw/Agentable/Experment_Agent/Agent/Group_3_python/Test-Agent/chat/model/model_adapter.py, class:AiroborosAdapter. 
Exist LOPE Defects in method load_model. Detail: The function 'load_model' does not have any fault tolerance mechanisms implemented for its inputs or outputs. Before calling 'load_model', there is no validation or error handling to ensure that 'model_path' is a valid string or that 'from_pretrained_kwargs' is a proper dictionary. If invalid inputs are provided, the function may raise an error. Additionally, after calling 'load_model', there is no error handling for the outputs (model and tokenizer). If the loading of the model or tokenizer fails, it will raise an exception without any fault tolerance measures in place to handle such failures. Therefore, both input and output lack fault tolerance.

file:/home/ningkw/Agentable/Experment_Agent/Agent/Group_3_python/Test-Agent/chat/model/model_adapter.py, class:OasstPythiaAdapter. 
Exist LOPE Defects in method load_model. Detail: The function 'load_model' does not implement any fault tolerance mechanisms for its inputs or outputs. There is no validation of the 'model_path' or 'from_pretrained_kwargs' parameters before they are passed to the superclass's 'load_model' method, which could lead to exceptions if invalid inputs are provided (e.g., if 'model_path' does not exist or is inaccessible). Similarly, after the call to the superclass's 'load_model', there is no error handling to manage potential issues in loading the model or tokenizer. If an error occurs, it will propagate up the call stack without any handling, which could lead to ungraceful failures. Therefore, both the input and output lack fault tolerance.

file:/home/ningkw/Agentable/Experment_Agent/Agent/Group_3_python/microagents/agents/microagent_manager.py, class:MicroAgentManager. 
Exist LOPE Defects in method get_or_create_agent. Detail: The function get_or_create_agent does not perform any validation or fault tolerance checks on its inputs (purpose, depth, sample_input, parent_agent) before calling self.agent_lifecycle.get_or_create_agent. This lack of input validation means that if any of these inputs are invalid (e.g., if 'purpose' is None, 'depth' is negative, or 'sample_input' is an unexpected type), it could lead to errors during execution. On the other hand, there is fault tolerance for the output after calling get_or_create_agent. The function includes a try-except block that logs any exceptions raised during the call to self.agent_lifecycle.get_or_create_agent, and it raises the exception again after logging. This means that while the output might not be successfully returned in case of an error, there is a mechanism in place to handle such errors gracefully by logging them.
 
file:/home/ningkw/Agentable/Experment_Agent/Agent/Group_3_python/microagents/gradio_ui/components.py, class:ChatInterface. 
Exist LOPE Defects in method chat_function. Detail: The function 'chat_function' directly calls 'self.agent_manager.process_user_input' with the 'message' parameter. There is no validation or error handling for the 'message' input before it is passed to 'process_user_input', meaning that if 'message' is malformed or of an unexpected type, it could lead to runtime errors. Similarly, there is no handling of the output from 'process_user_input'. If 'process_user_input' raises an exception or returns an unexpected result, 'chat_function' does not catch or manage those scenarios, which could lead to further issues in the program execution. Therefore, both inputs and outputs lack fault tolerance mechanisms.

file:/home/ningkw/Agentable/Experment_Agent/Agent/Group_3_python/AgentNeo/agentneo/tracing/base.py, class:BaseTracer. 
Exist LOPE Defects in method __enter__. Detail: The function '__enter__' calls the 'start()' method directly without any checks or validations on the inputs that may be required by 'start'. There is no error handling mechanism (such as try-except blocks) in place to handle potential exceptions that could arise from calling 'start'. Additionally, there is no verification of the output returned from 'start', meaning if 'start' were to return an unexpected result or raise an exception, it would not be handled, leading to a lack of fault tolerance for both the input before calling 'start' and the output after calling 'start'.

file:/home/ningkw/Agentable/Experment_Agent/Agent/Group_3_python/AgentNeo/agentneo/tracing/tracer.py, class:Tracer. 
Exist LOPE Defects in method start. Detail: The function 'start' does not have any input parameters, implying that there is no mechanism for validating or handling inputs before its execution. Since it relies on the state of the object (i.e., attributes like 'self.auto_instrument_llm'), there is no explicit check to ensure that these attributes are valid or properly initialized before calling 'super().start()'. Additionally, the method does not return any value or output, and thus there is no fault tolerance mechanism in place to handle potential errors or exceptions that may arise during the execution of 'super().start()' or 'self.instrument_llm_calls()'. If either of these methods fails, it would propagate an unhandled exception, indicating a lack of fault tolerance in both input handling and output management.

file:/home/ningkw/Agentable/Experment_Agent/Agent/Group_3_python/TaskWeaver/taskweaver/code_interpreter/code_interpreter/code_interpreter.py, class:CodeInterpreter. 
Exist LOPE Defects in method reply. Detail: The function 'reply' does not implement any explicit fault tolerance for its inputs before the call, particularly with the parameters 'memory' and 'prompt_log_path'. If these inputs are invalid or lead to unexpected behavior, the function may fail without any handling mechanism in place. In contrast, the output from the function does have fault tolerance mechanisms. The function checks various conditions after executing the code and provides error handling, including retry logic and updates to the post_proxy based on the success or failure of the operations. It also includes logging and tracing to track the state and errors, which helps in diagnosing issues post-execution.

file:/home/ningkw/Agentable/Experment_Agent/Agent/Group_3_python/TaskWeaver/taskweaver/planner/planner.py, class:Planner. 
Exist LOPE Defects in method compose_prompt. Detail: In the provided code, the function 'compress_rounds' is called within the 'compose_prompt' method. The input to 'compress_rounds' consists of the 'rounds' parameter and a lambda function that formats the rounds as a string. However, there is no prior validation or error handling performed on the 'rounds' input before it is passed to 'compress_rounds', which could lead to potential errors if 'rounds' is in an unexpected format or is None. Additionally, the output of 'compress_rounds' is unpacked into 'summary' and 'rounds' without any checks for None or valid data types. If 'compress_rounds' raises an exception or returns unexpected values, there are no mechanisms in place to handle such cases, indicating a lack of fault tolerance for both inputs and outputs.

file:/home/ningkw/Agentable/Experment_Agent/Agent/Group_3_python/TaskWeaver/taskweaver/code_interpreter/code_interpreter_plugin_only/code_interpreter_plugin_only.py, class:CodeInterpreterPluginOnly. 
Exist LOPE Defects in method reply. Detail: The function 'reply' takes in several parameters, including 'memory' and an optional 'prompt_log_path', but there are no checks or validations on these inputs before they are used in the function. Specifically, 'memory' is expected to be of type 'Memory', but there is no explicit validation to ensure that the input is valid or that it meets certain conditions (e.g., is not None, has required attributes, etc.). This lack of input validation can lead to runtime errors if invalid data is passed to the function.

file:/home/ningkw/Agentable/Experment_Agent/Agent/Group_3_python/TaskWeaver/taskweaver/code_interpreter/code_interpreter/code_generator.py, class:CodeGenerator. 
Exist LOPE Defects in method select_plugins_for_prompt. Detail: In the method select_plugins_for_prompt, the input to the function is the 'query' parameter, which is a string. There is no validation or error handling present before this input is passed to the plugin_select function. This means that if the query is malformed or not suitable for processing, it could lead to exceptions during the execution of plugin_select. Similarly, the output of plugin_select is assigned to 'selected_plugins' without any checks for its validity or the possibility of it being None or an empty list. While there is logging of the selected plugins and the selected plugin pool, there is no fault tolerance mechanism in place to handle potential errors or exceptions that could occur during the call to plugin_select. Therefore, both the input and output lack fault tolerance. The function 'reply' does not include any explicit fault tolerance mechanisms for the inputs before calling 'raw_text_to_post'. Specifically, the call to 'self.llm_api.chat_completion_stream' could potentially fail, and the output from this call is passed directly to 'raw_text_to_post' without any validation or error handling. Furthermore, the 'post_proxy' used as an argument for 'raw_text_to_post' is also not validated prior to its use. After the call to 'raw_text_to_post', there is no error handling for potential exceptions or unexpected outputs, meaning that if 'raw_text_to_post' fails or returns unexpected results, the subsequent logic that relies on its output could also fail. Overall, both the inputs and outputs lack fault tolerance. In the provided code, the function 'compress_rounds' is called with the 'rounds' variable, which is derived from the input parameter of the 'compose_prompt' function. There is no explicit validation or error handling for the 'rounds' input before it is passed to 'compress_rounds'. This means that if 'rounds' contains invalid data or is in an unexpected format, it could lead to runtime errors when 'compress_rounds' is executed. Similarly, there is no error handling for the output of 'compress_rounds'. The output, which is assigned to 'summary' and 'rounds', is used in subsequent processing without any checks to ensure it is valid. If 'compress_rounds' fails or returns an unexpected result, it could cause issues in the later parts of the function. Therefore, both inputs and outputs lack fault tolerance mechanisms.

file:/home/ningkw/Agentable/Experment_Agent/Agent/Group_3_python/TaskWeaver/taskweaver/code_interpreter/code_interpreter_plugin_only/code_generator_plugin_only.py, class:CodeGeneratorPluginOnly. 
Exist LOPE Defects in method select_plugins_for_prompt. Detail: In the provided function 'select_plugins_for_prompt', the method calls 'plugin_select' with the input 'user_query' and 'self.config.auto_plugin_selection_topk'. There is no validation or error handling for 'user_query' before it is passed to 'plugin_select', which means if 'user_query' is None or not in the expected format, it could lead to an error. Similarly, the output from 'plugin_select', which is stored in 'selected_plugins', is directly used to update the selected plugin pool without any checks to ensure that 'selected_plugins' is valid or non-empty. If 'plugin_select' raises an exception or returns an unexpected result (like an empty list), it could lead to further issues down the line. Therefore, there is a lack of fault tolerance for both the input and output in this context.

file:/home/ningkw/Agentable/Experment_Agent/Agent/Group_3_python/TaskWeaver/taskweaver/code_interpreter/code_interpreter_plugin_only/code_generator_plugin_only.py, class:CodeGeneratorPluginOnly. 
Exist LOPE Defects in method reply. Detail: In the provided method 'reply', the function 'chat_completion' is called with the parameters 'messages' and 'tools' derived from the 'prompt_with_tools' dictionary. Before this call, while there is an assertion to ensure 'post_proxy' is not None, there is no explicit validation of the inputs to 'chat_completion', such as checking if 'prompt_with_tools' contains valid data or if the values are of the expected types. This lack of checks indicates a lack of fault tolerance for the inputs. However, after calling 'chat_completion', the output 'llm_response' is checked for its 'role'. There are conditional statements that handle different roles ('assistant' and 'function') and appropriately update the 'post_proxy'. Additionally, if an unexpected response is encountered, an error is logged and a ValueError is raised. This indicates that there is fault tolerance for the output, as the function handles different scenarios based on the response received.